# Test Quality

With a failing check in place, I have an opportunity to look at the output,
and decide whether or not there are improvements to make.  Specifically,
I'm wondering whether I'll be able to easily recognize from the test
report what faults have been introduced.

```bash
python3 -m unittest test.test_chessboard
F
======================================================================
FAIL: test_random_board (test.test_chessboard.MyTestCase)
----------------------------------------------------------------------
Traceback (most recent call last):
  File "/Users/Danil/source/3rdparty/DanilSuits/chessKata-python/test/test_chessboard.py", line 10, in test_random_board
    self.assertTrue(actual)
AssertionError: None is not true

----------------------------------------------------------------------
Ran 1 test in 0.000s

FAILED (failures=1)
```

OK, the good news is that the report does tell me that I have a failing check,
and which one it is, and the line number to look at.
  
I don't think the traceback is doing a very good job of
telling me what fault has been discovered.

```bash
python3 -m unittest test.test_chessboard
F
======================================================================
FAIL: test_random_board (test.test_chessboard.MyTestCase)
----------------------------------------------------------------------
Traceback (most recent call last):
  File "/Users/Danil/source/3rdparty/DanilSuits/chessKata-python/test/test_chessboard.py", line 10, in test_random_board
    self.assertTrue(pieces)
AssertionError: None is not true

----------------------------------------------------------------------
Ran 1 test in 0.001s

FAILED (failures=1)
```

A better variable name gives me a small improvement

```bash
python3 -m unittest test.test_chessboard
F
======================================================================
FAIL: test_random_board (test.test_chessboard.MyTestCase)
----------------------------------------------------------------------
Traceback (most recent call last):
  File "/Users/Danil/source/3rdparty/DanilSuits/chessKata-python/test/test_chessboard.py", line 9, in test_random_board
    self.pieces_satisfy_specification(pieces)
  File "/Users/Danil/source/3rdparty/DanilSuits/chessKata-python/test/test_chessboard.py", line 12, in pieces_satisfy_specification
    self.pieces_are_truthy(pieces)
  File "/Users/Danil/source/3rdparty/DanilSuits/chessKata-python/test/test_chessboard.py", line 16, in pieces_are_truthy
    self.assertTrue(pieces)
AssertionError: None is not true

----------------------------------------------------------------------
Ran 1 test in 0.000s

FAILED (failures=1)
```

Adding additional method calls helps give some context

```bash
python3 -m unittest test.test_chessboard
F
======================================================================
FAIL: test_random_board (test.test_chessboard.MyTestCase)
----------------------------------------------------------------------
Traceback (most recent call last):
  File "/Users/Danil/source/3rdparty/DanilSuits/chessKata-python/test/test_chessboard.py", line 9, in test_random_board
    self.pieces_satisfy_specification(pieces)
  File "/Users/Danil/source/3rdparty/DanilSuits/chessKata-python/test/test_chessboard.py", line 12, in pieces_satisfy_specification
    self.pieces_are_truthy(pieces)
  File "/Users/Danil/source/3rdparty/DanilSuits/chessKata-python/test/test_chessboard.py", line 16, in pieces_are_truthy
    self.assertTrue(pieces, "Pieces should be truthy")
AssertionError: None is not true : Pieces should be truthy

----------------------------------------------------------------------
Ran 1 test in 0.001s

FAILED (failures=1)
```

Meh, the message just echos the stack information.

```bash
python3 -m unittest test.test_chessboard
F
======================================================================
FAIL: test_random_board (test.test_chessboard.RandomBoardTestCase)
----------------------------------------------------------------------
Traceback (most recent call last):
  File "/Users/Danil/source/3rdparty/DanilSuits/chessKata-python/test/test_chessboard.py", line 8, in test_random_board
    self.sut_satisifies_specification(system_under_test)
  File "/Users/Danil/source/3rdparty/DanilSuits/chessKata-python/test/test_chessboard.py", line 12, in sut_satisifies_specification
    self.pieces_satisfy_specification(pieces)
  File "/Users/Danil/source/3rdparty/DanilSuits/chessKata-python/test/test_chessboard.py", line 15, in pieces_satisfy_specification
    self.pieces_are_truthy(pieces)
  File "/Users/Danil/source/3rdparty/DanilSuits/chessKata-python/test/test_chessboard.py", line 19, in pieces_are_truthy
    self.assertTrue(pieces, "Pieces should be truthy")
AssertionError: None is not true : Pieces should be truthy

----------------------------------------------------------------------
Ran 1 test in 0.000s
```

Adding additional context doesn't improve things much.